Traceback (most recent call last):
  File "C:\Users\Jeet J\Anaconda3\lib\site-packages\urllib3\contrib\pyopenssl.py", line 441, in wrap_socket
    cnx.do_handshake()
  File "C:\Users\Jeet J\Anaconda3\lib\site-packages\OpenSSL\SSL.py", line 1716, in do_handshake
    self._raise_ssl_error(self._ssl, result)
  File "C:\Users\Jeet J\Anaconda3\lib\site-packages\OpenSSL\SSL.py", line 1449, in _raise_ssl_error
    raise SysCallError(-1, "Unexpected EOF")
OpenSSL.SSL.SysCallError: (-1, 'Unexpected EOF')

During handling of the above exception, another exception occurred:

Traceback (most recent call last):
  File "C:\Users\Jeet J\Anaconda3\lib\site-packages\urllib3\connectionpool.py", line 601, in urlopen
    chunked=chunked)
  File "C:\Users\Jeet J\Anaconda3\lib\site-packages\urllib3\connectionpool.py", line 346, in _make_request
    self._validate_conn(conn)
  File "C:\Users\Jeet J\Anaconda3\lib\site-packages\urllib3\connectionpool.py", line 850, in _validate_conn
    conn.connect()
  File "C:\Users\Jeet J\Anaconda3\lib\site-packages\urllib3\connection.py", line 326, in connect
    ssl_context=context)
  File "C:\Users\Jeet J\Anaconda3\lib\site-packages\urllib3\util\ssl_.py", line 329, in ssl_wrap_socket
    return context.wrap_socket(sock, server_hostname=server_hostname)
  File "C:\Users\Jeet J\Anaconda3\lib\site-packages\urllib3\contrib\pyopenssl.py", line 448, in wrap_socket
    raise ssl.SSLError('bad handshake: %r' % e)
ssl.SSLError: ("bad handshake: SysCallError(-1, 'Unexpected EOF')",)

During handling of the above exception, another exception occurred:

Traceback (most recent call last):
  File "C:\Users\Jeet J\Anaconda3\lib\site-packages\requests\adapters.py", line 440, in send
    timeout=timeout
  File "C:\Users\Jeet J\Anaconda3\lib\site-packages\urllib3\connectionpool.py", line 639, in urlopen
    _stacktrace=sys.exc_info()[2])
  File "C:\Users\Jeet J\Anaconda3\lib\site-packages\urllib3\util\retry.py", line 388, in increment
    raise MaxRetryError(_pool, url, error or ResponseError(cause))
urllib3.exceptions.MaxRetryError: HTTPSConnectionPool(host='www.bitstamp.net', port=443): Max retries exceeded with url: /api/ticker/ (Caused by SSLError(SSLError("bad handshake: SysCallError(-1, 'Unexpected EOF')",),))

During handling of the above exception, another exception occurred:

Traceback (most recent call last):
  File "<ipython-input-1-416d5f419b99>", line 24, in getBitcoinPrice
    r = requests.get(URL)
  File "C:\Users\Jeet J\Anaconda3\lib\site-packages\requests\api.py", line 72, in get
    return request('get', url, params=params, **kwargs)
  File "C:\Users\Jeet J\Anaconda3\lib\site-packages\requests\api.py", line 58, in request
    return session.request(method=method, url=url, **kwargs)
  File "C:\Users\Jeet J\Anaconda3\lib\site-packages\requests\sessions.py", line 508, in request
    resp = self.send(prep, **send_kwargs)
  File "C:\Users\Jeet J\Anaconda3\lib\site-packages\requests\sessions.py", line 618, in send
    r = adapter.send(request, **kwargs)
  File "C:\Users\Jeet J\Anaconda3\lib\site-packages\requests\adapters.py", line 506, in send
    raise SSLError(e, request=request)
requests.exceptions.SSLError: HTTPSConnectionPool(host='www.bitstamp.net', port=443): Max retries exceeded with url: /api/ticker/ (Caused by SSLError(SSLError("bad handshake: SysCallError(-1, 'Unexpected EOF')",),))
----------------------------------------------------------------------------------------------------

Traceback (most recent call last):
  File "C:\Users\Jeet J\Anaconda3\lib\site-packages\urllib3\connection.py", line 141, in _new_conn
    (self.host, self.port), self.timeout, **extra_kw)
  File "C:\Users\Jeet J\Anaconda3\lib\site-packages\urllib3\util\connection.py", line 83, in create_connection
    raise err
  File "C:\Users\Jeet J\Anaconda3\lib\site-packages\urllib3\util\connection.py", line 73, in create_connection
    sock.connect(sa)
TimeoutError: [WinError 10060] A connection attempt failed because the connected party did not properly respond after a period of time, or established connection failed because connected host has failed to respond

During handling of the above exception, another exception occurred:

Traceback (most recent call last):
  File "C:\Users\Jeet J\Anaconda3\lib\site-packages\urllib3\connectionpool.py", line 601, in urlopen
    chunked=chunked)
  File "C:\Users\Jeet J\Anaconda3\lib\site-packages\urllib3\connectionpool.py", line 346, in _make_request
    self._validate_conn(conn)
  File "C:\Users\Jeet J\Anaconda3\lib\site-packages\urllib3\connectionpool.py", line 850, in _validate_conn
    conn.connect()
  File "C:\Users\Jeet J\Anaconda3\lib\site-packages\urllib3\connection.py", line 284, in connect
    conn = self._new_conn()
  File "C:\Users\Jeet J\Anaconda3\lib\site-packages\urllib3\connection.py", line 150, in _new_conn
    self, "Failed to establish a new connection: %s" % e)
urllib3.exceptions.NewConnectionError: <urllib3.connection.VerifiedHTTPSConnection object at 0x0000023E15204630>: Failed to establish a new connection: [WinError 10060] A connection attempt failed because the connected party did not properly respond after a period of time, or established connection failed because connected host has failed to respond

During handling of the above exception, another exception occurred:

Traceback (most recent call last):
  File "C:\Users\Jeet J\Anaconda3\lib\site-packages\requests\adapters.py", line 440, in send
    timeout=timeout
  File "C:\Users\Jeet J\Anaconda3\lib\site-packages\urllib3\connectionpool.py", line 639, in urlopen
    _stacktrace=sys.exc_info()[2])
  File "C:\Users\Jeet J\Anaconda3\lib\site-packages\urllib3\util\retry.py", line 388, in increment
    raise MaxRetryError(_pool, url, error or ResponseError(cause))
urllib3.exceptions.MaxRetryError: HTTPSConnectionPool(host='www.bitstamp.net', port=443): Max retries exceeded with url: /api/ticker/ (Caused by NewConnectionError('<urllib3.connection.VerifiedHTTPSConnection object at 0x0000023E15204630>: Failed to establish a new connection: [WinError 10060] A connection attempt failed because the connected party did not properly respond after a period of time, or established connection failed because connected host has failed to respond',))

During handling of the above exception, another exception occurred:

Traceback (most recent call last):
  File "<ipython-input-1-416d5f419b99>", line 24, in getBitcoinPrice
    r = requests.get(URL)
  File "C:\Users\Jeet J\Anaconda3\lib\site-packages\requests\api.py", line 72, in get
    return request('get', url, params=params, **kwargs)
  File "C:\Users\Jeet J\Anaconda3\lib\site-packages\requests\api.py", line 58, in request
    return session.request(method=method, url=url, **kwargs)
  File "C:\Users\Jeet J\Anaconda3\lib\site-packages\requests\sessions.py", line 508, in request
    resp = self.send(prep, **send_kwargs)
  File "C:\Users\Jeet J\Anaconda3\lib\site-packages\requests\sessions.py", line 618, in send
    r = adapter.send(request, **kwargs)
  File "C:\Users\Jeet J\Anaconda3\lib\site-packages\requests\adapters.py", line 508, in send
    raise ConnectionError(e, request=request)
requests.exceptions.ConnectionError: HTTPSConnectionPool(host='www.bitstamp.net', port=443): Max retries exceeded with url: /api/ticker/ (Caused by NewConnectionError('<urllib3.connection.VerifiedHTTPSConnection object at 0x0000023E15204630>: Failed to establish a new connection: [WinError 10060] A connection attempt failed because the connected party did not properly respond after a period of time, or established connection failed because connected host has failed to respond',))
----------------------------------------------------------------------------------------------------

Traceback (most recent call last):
  File "C:\Users\Jeet J\Anaconda3\lib\site-packages\urllib3\connection.py", line 141, in _new_conn
    (self.host, self.port), self.timeout, **extra_kw)
  File "C:\Users\Jeet J\Anaconda3\lib\site-packages\urllib3\util\connection.py", line 60, in create_connection
    for res in socket.getaddrinfo(host, port, family, socket.SOCK_STREAM):
  File "C:\Users\Jeet J\Anaconda3\lib\socket.py", line 745, in getaddrinfo
    for res in _socket.getaddrinfo(host, port, family, type, proto, flags):
socket.gaierror: [Errno 11001] getaddrinfo failed

During handling of the above exception, another exception occurred:

Traceback (most recent call last):
  File "C:\Users\Jeet J\Anaconda3\lib\site-packages\urllib3\connectionpool.py", line 601, in urlopen
    chunked=chunked)
  File "C:\Users\Jeet J\Anaconda3\lib\site-packages\urllib3\connectionpool.py", line 346, in _make_request
    self._validate_conn(conn)
  File "C:\Users\Jeet J\Anaconda3\lib\site-packages\urllib3\connectionpool.py", line 850, in _validate_conn
    conn.connect()
  File "C:\Users\Jeet J\Anaconda3\lib\site-packages\urllib3\connection.py", line 284, in connect
    conn = self._new_conn()
  File "C:\Users\Jeet J\Anaconda3\lib\site-packages\urllib3\connection.py", line 150, in _new_conn
    self, "Failed to establish a new connection: %s" % e)
urllib3.exceptions.NewConnectionError: <urllib3.connection.VerifiedHTTPSConnection object at 0x0000023E15204D30>: Failed to establish a new connection: [Errno 11001] getaddrinfo failed

During handling of the above exception, another exception occurred:

Traceback (most recent call last):
  File "C:\Users\Jeet J\Anaconda3\lib\site-packages\requests\adapters.py", line 440, in send
    timeout=timeout
  File "C:\Users\Jeet J\Anaconda3\lib\site-packages\urllib3\connectionpool.py", line 639, in urlopen
    _stacktrace=sys.exc_info()[2])
  File "C:\Users\Jeet J\Anaconda3\lib\site-packages\urllib3\util\retry.py", line 388, in increment
    raise MaxRetryError(_pool, url, error or ResponseError(cause))
urllib3.exceptions.MaxRetryError: HTTPSConnectionPool(host='www.bitstamp.net', port=443): Max retries exceeded with url: /api/ticker/ (Caused by NewConnectionError('<urllib3.connection.VerifiedHTTPSConnection object at 0x0000023E15204D30>: Failed to establish a new connection: [Errno 11001] getaddrinfo failed',))

During handling of the above exception, another exception occurred:

Traceback (most recent call last):
  File "<ipython-input-1-416d5f419b99>", line 24, in getBitcoinPrice
    r = requests.get(URL)
  File "C:\Users\Jeet J\Anaconda3\lib\site-packages\requests\api.py", line 72, in get
    return request('get', url, params=params, **kwargs)
  File "C:\Users\Jeet J\Anaconda3\lib\site-packages\requests\api.py", line 58, in request
    return session.request(method=method, url=url, **kwargs)
  File "C:\Users\Jeet J\Anaconda3\lib\site-packages\requests\sessions.py", line 508, in request
    resp = self.send(prep, **send_kwargs)
  File "C:\Users\Jeet J\Anaconda3\lib\site-packages\requests\sessions.py", line 618, in send
    r = adapter.send(request, **kwargs)
  File "C:\Users\Jeet J\Anaconda3\lib\site-packages\requests\adapters.py", line 508, in send
    raise ConnectionError(e, request=request)
requests.exceptions.ConnectionError: HTTPSConnectionPool(host='www.bitstamp.net', port=443): Max retries exceeded with url: /api/ticker/ (Caused by NewConnectionError('<urllib3.connection.VerifiedHTTPSConnection object at 0x0000023E15204D30>: Failed to establish a new connection: [Errno 11001] getaddrinfo failed',))
----------------------------------------------------------------------------------------------------

Traceback (most recent call last):
  File "C:\Users\Jeet J\Anaconda3\lib\site-packages\urllib3\contrib\pyopenssl.py", line 441, in wrap_socket
    cnx.do_handshake()
  File "C:\Users\Jeet J\Anaconda3\lib\site-packages\OpenSSL\SSL.py", line 1716, in do_handshake
    self._raise_ssl_error(self._ssl, result)
  File "C:\Users\Jeet J\Anaconda3\lib\site-packages\OpenSSL\SSL.py", line 1449, in _raise_ssl_error
    raise SysCallError(-1, "Unexpected EOF")
OpenSSL.SSL.SysCallError: (-1, 'Unexpected EOF')

During handling of the above exception, another exception occurred:

Traceback (most recent call last):
  File "C:\Users\Jeet J\Anaconda3\lib\site-packages\urllib3\connectionpool.py", line 601, in urlopen
    chunked=chunked)
  File "C:\Users\Jeet J\Anaconda3\lib\site-packages\urllib3\connectionpool.py", line 346, in _make_request
    self._validate_conn(conn)
  File "C:\Users\Jeet J\Anaconda3\lib\site-packages\urllib3\connectionpool.py", line 850, in _validate_conn
    conn.connect()
  File "C:\Users\Jeet J\Anaconda3\lib\site-packages\urllib3\connection.py", line 326, in connect
    ssl_context=context)
  File "C:\Users\Jeet J\Anaconda3\lib\site-packages\urllib3\util\ssl_.py", line 329, in ssl_wrap_socket
    return context.wrap_socket(sock, server_hostname=server_hostname)
  File "C:\Users\Jeet J\Anaconda3\lib\site-packages\urllib3\contrib\pyopenssl.py", line 448, in wrap_socket
    raise ssl.SSLError('bad handshake: %r' % e)
ssl.SSLError: ("bad handshake: SysCallError(-1, 'Unexpected EOF')",)

During handling of the above exception, another exception occurred:

Traceback (most recent call last):
  File "C:\Users\Jeet J\Anaconda3\lib\site-packages\requests\adapters.py", line 440, in send
    timeout=timeout
  File "C:\Users\Jeet J\Anaconda3\lib\site-packages\urllib3\connectionpool.py", line 639, in urlopen
    _stacktrace=sys.exc_info()[2])
  File "C:\Users\Jeet J\Anaconda3\lib\site-packages\urllib3\util\retry.py", line 388, in increment
    raise MaxRetryError(_pool, url, error or ResponseError(cause))
urllib3.exceptions.MaxRetryError: HTTPSConnectionPool(host='www.bitstamp.net', port=443): Max retries exceeded with url: /api/ticker/ (Caused by SSLError(SSLError("bad handshake: SysCallError(-1, 'Unexpected EOF')",),))

During handling of the above exception, another exception occurred:

Traceback (most recent call last):
  File "<ipython-input-1-416d5f419b99>", line 24, in getBitcoinPrice
    r = requests.get(URL)
  File "C:\Users\Jeet J\Anaconda3\lib\site-packages\requests\api.py", line 72, in get
    return request('get', url, params=params, **kwargs)
  File "C:\Users\Jeet J\Anaconda3\lib\site-packages\requests\api.py", line 58, in request
    return session.request(method=method, url=url, **kwargs)
  File "C:\Users\Jeet J\Anaconda3\lib\site-packages\requests\sessions.py", line 508, in request
    resp = self.send(prep, **send_kwargs)
  File "C:\Users\Jeet J\Anaconda3\lib\site-packages\requests\sessions.py", line 618, in send
    r = adapter.send(request, **kwargs)
  File "C:\Users\Jeet J\Anaconda3\lib\site-packages\requests\adapters.py", line 506, in send
    raise SSLError(e, request=request)
requests.exceptions.SSLError: HTTPSConnectionPool(host='www.bitstamp.net', port=443): Max retries exceeded with url: /api/ticker/ (Caused by SSLError(SSLError("bad handshake: SysCallError(-1, 'Unexpected EOF')",),))
----------------------------------------------------------------------------------------------------

Traceback (most recent call last):
  File "C:\Users\Jeet J\Anaconda3\lib\site-packages\urllib3\contrib\pyopenssl.py", line 441, in wrap_socket
    cnx.do_handshake()
  File "C:\Users\Jeet J\Anaconda3\lib\site-packages\OpenSSL\SSL.py", line 1716, in do_handshake
    self._raise_ssl_error(self._ssl, result)
  File "C:\Users\Jeet J\Anaconda3\lib\site-packages\OpenSSL\SSL.py", line 1449, in _raise_ssl_error
    raise SysCallError(-1, "Unexpected EOF")
OpenSSL.SSL.SysCallError: (-1, 'Unexpected EOF')

During handling of the above exception, another exception occurred:

Traceback (most recent call last):
  File "C:\Users\Jeet J\Anaconda3\lib\site-packages\urllib3\connectionpool.py", line 601, in urlopen
    chunked=chunked)
  File "C:\Users\Jeet J\Anaconda3\lib\site-packages\urllib3\connectionpool.py", line 346, in _make_request
    self._validate_conn(conn)
  File "C:\Users\Jeet J\Anaconda3\lib\site-packages\urllib3\connectionpool.py", line 850, in _validate_conn
    conn.connect()
  File "C:\Users\Jeet J\Anaconda3\lib\site-packages\urllib3\connection.py", line 326, in connect
    ssl_context=context)
  File "C:\Users\Jeet J\Anaconda3\lib\site-packages\urllib3\util\ssl_.py", line 329, in ssl_wrap_socket
    return context.wrap_socket(sock, server_hostname=server_hostname)
  File "C:\Users\Jeet J\Anaconda3\lib\site-packages\urllib3\contrib\pyopenssl.py", line 448, in wrap_socket
    raise ssl.SSLError('bad handshake: %r' % e)
ssl.SSLError: ("bad handshake: SysCallError(-1, 'Unexpected EOF')",)

During handling of the above exception, another exception occurred:

Traceback (most recent call last):
  File "C:\Users\Jeet J\Anaconda3\lib\site-packages\requests\adapters.py", line 440, in send
    timeout=timeout
  File "C:\Users\Jeet J\Anaconda3\lib\site-packages\urllib3\connectionpool.py", line 639, in urlopen
    _stacktrace=sys.exc_info()[2])
  File "C:\Users\Jeet J\Anaconda3\lib\site-packages\urllib3\util\retry.py", line 388, in increment
    raise MaxRetryError(_pool, url, error or ResponseError(cause))
urllib3.exceptions.MaxRetryError: HTTPSConnectionPool(host='www.bitstamp.net', port=443): Max retries exceeded with url: /api/ticker/ (Caused by SSLError(SSLError("bad handshake: SysCallError(-1, 'Unexpected EOF')",),))

During handling of the above exception, another exception occurred:

Traceback (most recent call last):
  File "<ipython-input-1-416d5f419b99>", line 24, in getBitcoinPrice
    r = requests.get(URL)
  File "C:\Users\Jeet J\Anaconda3\lib\site-packages\requests\api.py", line 72, in get
    return request('get', url, params=params, **kwargs)
  File "C:\Users\Jeet J\Anaconda3\lib\site-packages\requests\api.py", line 58, in request
    return session.request(method=method, url=url, **kwargs)
  File "C:\Users\Jeet J\Anaconda3\lib\site-packages\requests\sessions.py", line 508, in request
    resp = self.send(prep, **send_kwargs)
  File "C:\Users\Jeet J\Anaconda3\lib\site-packages\requests\sessions.py", line 618, in send
    r = adapter.send(request, **kwargs)
  File "C:\Users\Jeet J\Anaconda3\lib\site-packages\requests\adapters.py", line 506, in send
    raise SSLError(e, request=request)
requests.exceptions.SSLError: HTTPSConnectionPool(host='www.bitstamp.net', port=443): Max retries exceeded with url: /api/ticker/ (Caused by SSLError(SSLError("bad handshake: SysCallError(-1, 'Unexpected EOF')",),))
----------------------------------------------------------------------------------------------------

